Workbook

Sheet Start Here
A1: ABACC Annual Compensation Survey 2026
A2: Data Collection Worksheet
A3: Administered by the Casagrande Institute, in collaboration with ABACC.
A5: What this is
A6: The survey asks for figures that often sit in different offices. Use this worksheet to collect them first, then enter them in the online survey in one sitting. The survey also lets you attach the completed worksheet (optional).
A8: How to use it
A9: 1. Share this file with the colleagues who hold each set of figures. The table below shows who usually has what.
A10: 2. Enter values only in the shaded cells. Every other cell is locked.
A11: 3. Watch the Check column. OK means the entry is complete. To do means it is still blank. Check means the entry cannot be right (not a number, negative, or an unneeded entry). Confirm means the value is outside the expected range or otherwise unusual - it is allowed, but make sure it is right. The survey applies the same checks.
A12: 4. When every section shows nothing left to do, open your survey link (sent Monday, October 19, 2026) and type in the values. The survey asks the same questions in the same order.
A13: 5. In the survey, type numbers without commas, dollar signs, or percent signs. This worksheet adds commas for you so large numbers are easier to read.
A14: 6. Submit the survey by Friday, November 6, 2026.
... A22: Progress
A23: Section | B23: Usually held by | C23: Complete | D23: To do | E23: To review
A24: 1 Institution | B24: Finance; Registrar or Institutional Research for student FTE | C24: =COUNTIF('1 Institution'!$G$6:$G$15,"OK")+COUNTIF('1 Institution'!$G$6:$G$15,"Not needed") | D24: =COUNTIF('1 Institution'!$G$6:$G$15,"To do")+COUNTIF('1 Institution'!$G$6:$G$15,"Answer*") | E24: =COUNTIF('1 Institution'!$G$6:$G$15,"Check*")+COUNTIF('1 Institution'!$G$6:$G$15,"Confirm*")
A25: 2 Admin Leaders | B25: Human Resources | C25: =COUNTIF('2 Admin Leaders'!$I$11:$I$24,"OK")+COUNTIF('2 Admin Leaders'!$I$11:$I$24,"Not needed") | D25: =COUNTIF('2 Admin Leaders'!$I$11:$I$24,"To do")+COUNTIF('2 Admin Leaders'!$I$11:$I$24,"Answer*") | E25: =COUNTIF('2 Admin Leaders'!$I$11:$I$24,"Check*")+COUNTIF('2 Admin Leaders'!$I$11:$I$24,"Confirm*")
A26: 3 President | B26: Human Resources, the President's office, or the Board | C26: =COUNTIF('3 President'!$G$7:$G$41,"OK")+COUNTIF('3 President'!$G$7:$G$41,"Not needed") | D26: =COUNTIF('3 President'!$G$7:$G$41,"To do")+COUNTIF('3 President'!$G$7:$G$41,"Answer*") | E26: =COUNTIF('3 President'!$G$7:$G$41,"Check*")+COUNTIF('3 President'!$G$7:$G$41,"Confirm*")
A27: 4 Additional | B27: President's office; Human Resources | C27: =COUNTIF('4 Additional'!$G$6:$G$9,"OK")+COUNTIF('4 Additional'!$G$6:$G$9,"Not needed") | D27: =COUNTIF('4 Additional'!$G$6:$G$9,"To do")+COUNTIF('4 Additional'!$G$6:$G$9,"Answer*") | E27: =COUNTIF('4 Additional'!$G$6:$G$9,"Check*")+COUNTIF('4 Additional'!$G$6:$G$9,"Confirm*")
A29: Confidentiality
A30: Survey responses are confidential. The Casagrande Institute does not disclose individual responses to anyone, including ABACC. Results are reported only in summary, and never for a group of fewer than five institutions.
A32: Questions
A33: David J. Bauer, Ph.D., Director, Casagrande Institute - djbauer@viterbo.edu - 608-796-3617

Sheet 1 Institution
A1: Section 1: Institutional Data
A2: Used to group institutions for reporting. Individual values are never reported, and any reported group includes at least five institutions. If your fiscal year runs January to December, your last fiscal year is calendar 2025 and your current fiscal year is calendar 2026.
A3: Enter values only in the shaded cells in column C. Column G tells you whether each entry is complete.
A5: Item | B5: Question | C5: Your entry | D5: How to enter | E5: Example | F5: Usually held by | G5: Check
A6: 1.1 | B6: Highest degree granted | D6: Choose from the list. | E6: Master's | F6: Finance / Registrar | G6: =IF(C6="","To do","OK")
A7: 1.2 | B7: Last day of your fiscal year | D7: Choose from the list. | E7: June 30 | F7: Finance | G7: =IF(C7="","To do","OK")
A8: 1.3 | B8: Fiscal year end date [Answer only if 1.2 is Other.] | D8: Month and day. | F8: Finance | G8: =IF(C7="",IF(C8="","Answer 1.2 first","Check: answer 1.2 first"),IF(C7="Other",IF(C8="","To do","OK"),IF(C8="","Not needed","Check: not needed - clear this entry")))
A9: 1.4 | B9: Total endowment - market value at the end of your last fiscal year (FY 2025-26) ($) | D9: Whole dollars. Enter 0 if there is no endowment. | E9: 14900000 | F9: Finance | G9: =IF(C9="","To do",IF(NOT(ISNUMBER(C9)),"Check: enter a number only, without symbols",IF(OR(C9<0,C9>99999999999),"Check: must be from 0 to 99,999,999,999",IF(C9<>INT(C9),"Check: whole numbers only",IF(OR(C9<0,C9>500000000),"Confirm: outside the expected range (0 to 500,000,000)","OK")))))
A10: 1.5 | B10: Total annual expenses for your last fiscal year (FY 2025-26) ($) | D10: Whole dollars. Enter the full amount (23000000, not 23 or 23000). | E10: 23000000 | F10: Finance | G10: =IF(C10="","To do",IF(NOT(ISNUMBER(C10)),"Check: enter a number only, without symbols",IF(OR(C10<0,C10>99999999999),"Check: must be from 0 to 99,999,999,999",IF(C10<>INT(C10),"Check: whole numbers only",IF(OR(C10<500000,C10>300000000),"Confirm: outside the expected range (500,000 to 300,000,000)",IF(C10<1000000,"Confirm: under $1 million - enter the full amount, not thousands","OK"))))))
A11: 1.6 | B11: Undergraduate student full-time equivalent (FTE) for Fall 2026 | D11: FTE = full-time students + 1/3 of part-time students. Whole number. | E11: 812 | F11: Registrar / Institutional Research | G11: =IF(C11="","To do",IF(NOT(ISNUMBER(C11)),"Check: enter a number only, without symbols",IF(OR(C11<0,C11>999999),"Check: must be from 0 to 999,999",IF(C11<>INT(C11),"Check: whole numbers only",IF(OR(C11<0,C11>15000),"Confirm: outside the expected range (0 to 15,000)",IF(C11<25,"Confirm: fewer than 25 undergraduate FTE students","OK"))))))
A12: 1.7 | B12: Graduate student full-time equivalent (FTE) for Fall 2026 | D12: FTE = full-time students + 1/3 of part-time students. Whole number. Enter 0 if there are no graduate students. | E12: 76 | F12: Registrar / Institutional Research | G12: =IF(C12="","To do",IF(NOT(ISNUMBER(C12)),"Check: enter a number only, without symbols",IF(OR(C12<0,C12>999999),"Check: must be from 0 to 999,999",IF(C12<>INT(C12),"Check: whole numbers only",IF(OR(C12<0,C12>5000),"Confirm: outside the expected range (0 to 5,000)","OK")))))
A13: 1.8 | B13: Percentage of salary budgeted for increases in the last fiscal year (FY 2025-26) | D13: Percent with up to one decimal. Enter 3 for 3%, not 0.03. | E13: 2 | F13: Finance / HR | G13: =IF(C13="","To do",IF(NOT(ISNUMBER(C13)),"Check: enter a number only, without symbols",IF(OR(C13<0,C13>999),"Check: must be from 0 to 999",IF(OR(C13<0,C13>15),"Confirm: outside the expected range (0 to 15)",IF(C13>10,"Confirm: over 10%","OK")))))
A14: 1.9 | B14: Percentage of salary budgeted for increases in the current fiscal year (FY 2026-27) | D14: Percent with up to one decimal. Enter 3 for 3%, not 0.03. | E14: 2.5 | F14: Finance / HR | G14: =IF(C14="","To do",IF(NOT(ISNUMBER(C14)),"Check: enter a number only, without symbols",IF(OR(C14<0,C14>999),"Check: must be from 0 to 999",IF(OR(C14<0,C14>15),"Confirm: outside the expected range (0 to 15)",IF(C14>10,"Confirm: over 10%","OK")))))
A15: 1.10 | B15: Maximum employer contribution, as a percentage of salary, that an employee can earn in the qualified retirement plan | D15: Percent with up to one decimal. Enter 3 for 3%, not 0.03. | E15: 5 | F15: HR | G15: =IF(C15="","To do",IF(NOT(ISNUMBER(C15)),"Check: enter a number only, without symbols",IF(OR(C15<0,C15>999),"Check: must be from 0 to 999",IF(OR(C15<0,C15>20),"Confirm: outside the expected range (0 to 20)","OK"))))

Sheet 2 Admin Leaders
A1: Section 2: Administrative Leadership Compensation
A2: For each role, say whether it exists with a full-time incumbent as of October 1, 2026. If Yes, complete the row.
A3: Report the senior-most person responsible for each function, whatever their title. Report each person once. If one person covers two roles, report them under the primary role and explain in the notes.
A4: Reports to President: choose Yes if this person reports directly to the President / CEO, and No if they report to another administrator.
A5: Base salary: annual (12-month) amount, not monthly or per pay period. Whole dollars. Leave out bonus and allowances.
A6: Bonus: most recent annual bonus paid (for FY 2025-26). Enter 0 if none. Years: completed years in this role at this institution only. Enter 0 for the first year.
A7: Usually held by: Human Resources.
A9: Role | B9: What this role covers | C9: Full-time incumbent? | D9: Reports directly to President / CEO? | E9: Annual base salary ($) | F9: Most recent bonus paid ($) | G9: Completed years in role | H9: Notes (optional) | I9: Check
A10: Example: Chief Human Resources Officer | B10: A filled-in row looks like this. | C10: Yes | D10: No | E10: 98000 | F10: 0 | G10: 6 | H10: Director of HR; reports to the CFO
A11: Chief Business / Financial Officer | B11: Senior-most administrator for financial and business affairs - typically budget, accounting, investments, and business operations. Often titled Vice President for Finance or for Business Affairs. | I11: =IF(C11="",IF(COUNTA(D11:G11)>0,"Check: choose Yes or No for incumbent","To do"),IF(C11="No",IF(COUNTA(D11:G11)>0,"Check: clear the row or choose Yes","OK"),IF(OR(D11="",COUNTA(E11:G11)<3),"To do",IF(COUNT(E11:G11)<3,"Check: enter numbers only, without symbols",IF(OR(E11<0,F11<0,G11<0,E11<>INT(E11),F11<>INT(F11),G11<>INT(G11)),"Check: whole numbers, not negative",IF(OR(E11<30000,E11>500000),"Confirm: base salary outside the expected range (30,000 to 500,000)",IF(OR(F11<0,F11>100000),"Confirm: bonus outside the expected range (0 to 100,000)",IF(OR(G11<0,G11>40),"Confirm: years outside the expected range (0 to 40)",IF(E11<40000,"Confirm: base under $40,000 - enter the annual amount",IF(F11>50000,"Confirm: bonus over $50,000","OK"))))))))))
A12: Chief Operating Officer | B12: Senior administrator over several operational areas, such as facilities, auxiliary services, human resources, and technology. Often titled Chief Operating Officer or Executive Vice President. If this person is also the Chief Business / Financial Officer, report them there instead. | I12: =IF(C12="",IF(COUNTA(D12:G12)>0,"Check: choose Yes or No for incumbent","To do"),IF(C12="No",IF(COUNTA(D12:G12)>0,"Check: clear the row or choose Yes","OK"),IF(OR(D12="",COUNTA(E12:G12)<3),"To do",IF(COUNT(E12:G12)<3,"Check: enter numbers only, without symbols",IF(OR(E12<0,F12<0,G12<0,E12<>INT(E12),F12<>INT(F12),G12<>INT(G12)),"Check: whole numbers, not negative",IF(OR(E12<30000,E12>500000),"Confirm: base salary outside the expected range (30,000 to 500,000)",IF(OR(F12<0,F12>100000),"Confirm: bonus outside the expected range (0 to 100,000)",IF(OR(G12<0,G12>40),"Confirm: years outside the expected range (0 to 40)",IF(E12<40000,"Confirm: base under $40,000 - enter the annual amount",IF(F12>50000,"Confirm: bonus over $50,000","OK"))))))))))
A13: Controller | B13: Senior-most accounting administrator - typically accounting, payroll, and financial reporting - under the Chief Business / Financial Officer. Often titled Controller or Director of Finance. | I13: =IF(C13="",IF(COUNTA(D13:G13)>0,"Check: choose Yes or No for incumbent","To do"),IF(C13="No",IF(COUNTA(D13:G13)>0,"Check: clear the row or choose Yes","OK"),IF(OR(D13="",COUNTA(E13:G13)<3),"To do",IF(COUNT(E13:G13)<3,"Check: enter numbers only, without symbols",IF(OR(E13<0,F13<0,G13<0,E13<>INT(E13),F13<>INT(F13),G13<>INT(G13)),"Check: whole numbers, not negative",IF(OR(E13<30000,E13>500000),"Confirm: base salary outside the expected range (30,000 to 500,000)",IF(OR(F13<0,F13>100000),"Confirm: bonus outside the expected range (0 to 100,000)",IF(OR(G13<0,G13>40),"Confirm: years outside the expected range (0 to 40)",IF(E13<40000,"Confirm: base under $40,000 - enter the annual amount",IF(F13>50000,"Confirm: bonus over $50,000","OK"))))))))))
A14: Chief Human Resources Officer | B14: Senior-most administrator for human resources - typically employment, benefits, compensation, and personnel records. Report this person whatever the title (Vice President, Director) or reporting line. | I14: =IF(C14="",IF(COUNTA(D14:G14)>0,"Check: choose Yes or No for incumbent","To do"),IF(C14="No",IF(COUNTA(D14:G14)>0,"Check: clear the row or choose Yes","OK"),IF(OR(D14="",COUNTA(E14:G14)<3),"To do",IF(COUNT(E14:G14)<3,"Check: enter numbers only, without symbols",IF(OR(E14<0,F14<0,G14<0,E14<>INT(E14),F14<>INT(F14),G14<>INT(G14)),"Check: whole numbers, not negative",IF(OR(E14<30000,E14>500000),"Confirm: base salary outside the expected range (30,000 to 500,000)",IF(OR(F14<0,F14>100000),"Confirm: bonus outside the expected range (0 to 100,000)",IF(OR(G14<0,G14>40),"Confirm: years outside the expected range (0 to 40)",IF(E14<40000,"Confirm: base under $40,000 - enter the annual amount",IF(F14>50000,"Confirm: bonus over $50,000","OK"))))))))))
A15: Chief Information / Technology Officer | B15: Senior-most administrator for information technology systems and strategy. | I15: =IF(C15="",IF(COUNTA(D15:G15)>0,"Check: choose Yes or No for incumbent","To do"),IF(C15="No",IF(COUNTA(D15:G15)>0,"Check: clear the row or choose Yes","OK"),IF(OR(D15="",COUNTA(E15:G15)<3),"To do",IF(COUNT(E15:G15)<3,"Check: enter numbers only, without symbols",IF(OR(E15<0,F15<0,G15<0,E15<>INT(E15),F15<>INT(F15),G15<>INT(G15)),"Check: whole numbers, not negative",IF(OR(E15<30000,E15>500000),"Confirm: base salary outside the expected range (30,000 to 500,000)",IF(OR(F15<0,F15>100000),"Confirm: bonus outside the expected range (0 to 100,000)",IF(OR(G15<0,G15>40),"Confirm: years outside the expected range (0 to 40)",IF(E15<40000,"Confirm: base under $40,000 - enter the annual amount",IF(F15>50000,"Confirm: bonus over $50,000","OK"))))))))))
A16: Chief Academic Officer | B16: Senior-most administrator for the academic program - typically faculty, curriculum, and academic planning. Often titled Provost, Vice President for Academic Affairs, or Academic Dean. | I16: =IF(C16="",IF(COUNTA(D16:G16)>0,"Check: choose Yes or No for incumbent","To do"),IF(C16="No",IF(COUNTA(D16:G16)>0,"Check: clear the row or choose Yes","OK"),IF(OR(D16="",COUNTA(E16:G16)<3),"To do",IF(COUNT(E16:G16)<3,"Check: enter numbers only, without symbols",IF(OR(E16<0,F16<0,G16<0,E16<>INT(E16),F16<>INT(F16),G16<>INT(G16)),"Check: whole numbers, not negative",IF(OR(E16<30000,E16>500000),"Confirm: base salary outside the expected range (30,000 to 500,000)",IF(OR(F16<0,F16>100000),"Confirm: bonus outside the expected range (0 to 100,000)",IF(OR(G16<0,G16>40),"Confirm: years outside the expected range (0 to 40)",IF(E16<40000,"Confirm: base under $40,000 - enter the annual amount",IF(F16>50000,"Confirm: bonus over $50,000","OK"))))))))))
A17: Chief Enrollment Management Officer | B17: Senior-most administrator for student recruitment and retention - typically admissions, and often financial aid and registration. | I17: =IF(C17="",IF(COUNTA(D17:G17)>0,"Check: choose Yes or No for incumbent","To do"),IF(C17="No",IF(COUNTA(D17:G17)>0,"Check: clear the row or choose Yes","OK"),IF(OR(D17="",COUNTA(E17:G17)<3),"To do",IF(COUNT(E17:G17)<3,"Check: enter numbers only, without symbols",IF(OR(E17<0,F17<0,G17<0,E17<>INT(E17),F17<>INT(F17),G17<>INT(G17)),"Check: whole numbers, not negative",IF(OR(E17<30000,E17>500000),"Confirm: base salary outside the expected range (30,000 to 500,000)",IF(OR(F17<0,F17>100000),"Confirm: bonus outside the expected range (0 to 100,000)",IF(OR(G17<0,G17>40),"Confirm: years outside the expected range (0 to 40)",IF(E17<40000,"Confirm: base under $40,000 - enter the annual amount",IF(F17>50000,"Confirm: bonus over $50,000","OK"))))))))))
A18: Chief Student Affairs Officer | B18: Senior-most administrator for student services and student life - typically residence life, student conduct, counseling, and student activities. | I18: =IF(C18="",IF(COUNTA(D18:G18)>0,"Check: choose Yes or No for incumbent","To do"),IF(C18="No",IF(COUNTA(D18:G18)>0,"Check: clear the row or choose Yes","OK"),IF(OR(D18="",COUNTA(E18:G18)<3),"To do",IF(COUNT(E18:G18)<3,"Check: enter numbers only, without symbols",IF(OR(E18<0,F18<0,G18<0,E18<>INT(E18),F18<>INT(F18),G18<>INT(G18)),"Check: whole numbers, not negative",IF(OR(E18<30000,E18>500000),"Confirm: base salary outside the expected range (30,000 to 500,000)",IF(OR(F18<0,F18>100000),"Confirm: bonus outside the expected range (0 to 100,000)",IF(OR(G18<0,G18>40),"Confirm: years outside the expected range (0 to 40)",IF(E18<40000,"Confirm: base under $40,000 - enter the annual amount",IF(F18>50000,"Confirm: bonus over $50,000","OK"))))))))))
A19: Chief Mission Officer | B19: Senior-most administrator for the institution's faith mission - typically mission integration, spiritual formation, campus ministry, and chapel. Often titled Vice President for Mission, Vice President for Spiritual Life, Campus Pastor, or Chaplain. Report this person whatever the title. | I19: =IF(C19="",IF(COUNTA(D19:G19)>0,"Check: choose Yes or No for incumbent","To do"),IF(C19="No",IF(COUNTA(D19:G19)>0,"Check: clear the row or choose Yes","OK"),IF(OR(D19="",COUNTA(E19:G19)<3),"To do",IF(COUNT(E19:G19)<3,"Check: enter numbers only, without symbols",IF(OR(E19<0,F19<0,G19<0,E19<>INT(E19),F19<>INT(F19),G19<>INT(G19)),"Check: whole numbers, not negative",IF(OR(E19<30000,E19>500000),"Confirm: base salary outside the expected range (30,000 to 500,000)",IF(OR(F19<0,F19>100000),"Confirm: bonus outside the expected range (0 to 100,000)",IF(OR(G19<0,G19>40),"Confirm: years outside the expected range (0 to 40)",IF(E19<40000,"Confirm: base under $40,000 - enter the annual amount",IF(F19>50000,"Confirm: bonus over $50,000","OK"))))))))))
A20: Athletics Director | B20: Senior-most administrator for intercollegiate athletics programs, staff, and facilities. | I20: =IF(C20="",IF(COUNTA(D20:G20)>0,"Check: choose Yes or No for incumbent","To do"),IF(C20="No",IF(COUNTA(D20:G20)>0,"Check: clear the row or choose Yes","OK"),IF(OR(D20="",COUNTA(E20:G20)<3),"To do",IF(COUNT(E20:G20)<3,"Check: enter numbers only, without symbols",IF(OR(E20<0,F20<0,G20<0,E20<>INT(E20),F20<>INT(F20),G20<>INT(G20)),"Check: whole numbers, not negative",IF(OR(E20<30000,E20>500000),"Confirm: base salary outside the expected range (30,000 to 500,000)",IF(OR(F20<0,F20>100000),"Confirm: bonus outside the expected range (0 to 100,000)",IF(OR(G20<0,G20>40),"Confirm: years outside the expected range (0 to 40)",IF(E20<40000,"Confirm: base under $40,000 - enter the annual amount",IF(F20>50000,"Confirm: bonus over $50,000","OK"))))))))))
A21: Chief Development Officer | B21: Senior-most administrator for fundraising and advancement, often including alumni relations. | I21: =IF(C21="",IF(COUNTA(D21:G21)>0,"Check: choose Yes or No for incumbent","To do"),IF(C21="No",IF(COUNTA(D21:G21)>0,"Check: clear the row or choose Yes","OK"),IF(OR(D21="",COUNTA(E21:G21)<3),"To do",IF(COUNT(E21:G21)<3,"Check: enter numbers only, without symbols",IF(OR(E21<0,F21<0,G21<0,E21<>INT(E21),F21<>INT(F21),G21<>INT(G21)),"Check: whole numbers, not negative",IF(OR(E21<30000,E21>500000),"Confirm: base salary outside the expected range (30,000 to 500,000)",IF(OR(F21<0,F21>100000),"Confirm: bonus outside the expected range (0 to 100,000)",IF(OR(G21<0,G21>40),"Confirm: years outside the expected range (0 to 40)",IF(E21<40000,"Confirm: base under $40,000 - enter the annual amount",IF(F21>50000,"Confirm: bonus over $50,000","OK"))))))))))
A22: Chief Marketing / Communications Officer | B22: Senior-most administrator for marketing, communications, and public relations - typically branding, web and media, and public relations. | I22: =IF(C22="",IF(COUNTA(D22:G22)>0,"Check: choose Yes or No for incumbent","To do"),IF(C22="No",IF(COUNTA(D22:G22)>0,"Check: clear the row or choose Yes","OK"),IF(OR(D22="",COUNTA(E22:G22)<3),"To do",IF(COUNT(E22:G22)<3,"Check: enter numbers only, without symbols",IF(OR(E22<0,F22<0,G22<0,E22<>INT(E22),F22<>INT(F22),G22<>INT(G22)),"Check: whole numbers, not negative",IF(OR(E22<30000,E22>500000),"Confirm: base salary outside the expected range (30,000 to 500,000)",IF(OR(F22<0,F22>100000),"Confirm: bonus outside the expected range (0 to 100,000)",IF(OR(G22<0,G22>40),"Confirm: years outside the expected range (0 to 40)",IF(E22<40000,"Confirm: base under $40,000 - enter the annual amount",IF(F22>50000,"Confirm: bonus over $50,000","OK"))))))))))
... A24: General Counsel | B24: Senior-most attorney on the institution's payroll, responsible for its legal affairs. Do not report outside counsel. | I24: =IF(C24="",IF(COUNTA(D24:G24)>0,"Check: choose Yes or No for incumbent","To do"),IF(C24="No",IF(COUNTA(D24:G24)>0,"Check: clear the row or choose Yes","OK"),IF(OR(D24="",COUNTA(E24:G24)<3),"To do",IF(COUNT(E24:G24)<3,"Check: enter numbers only, without symbols",IF(OR(E24<0,F24<0,G24<0,E24<>INT(E24),F24<>INT(F24),G24<>INT(G24)),"Check: whole numbers, not negative",IF(OR(E24<30000,E24>500000),"Confirm: base salary outside the expected range (30,000 to 500,000)",IF(OR(F24<0,F24>100000),"Confirm: bonus outside the expected range (0 to 100,000)",IF(OR(G24<0,G24>40),"Confirm: years outside the expected range (0 to 40)",IF(E24<40000,"Confirm: base under $40,000 - enter the annual amount",IF(F24>50000,"Confirm: bonus over $50,000","OK"))))))))))

Sheet 3 President
A1: Section 3: President / CEO Compensation
A2: All amounts are for the current President / CEO as of October 1, 2026 unless an item says otherwise.
A3: Enter values only in the shaded cells in column C. Column G tells you whether each entry is complete.
A5: Item | B5: Question | C5: Your entry | D5: How to enter | E5: Example | F5: Usually held by | G5: Check
A6: 3A: Base salary and bonus
A7: 3A.1 | B7: President / CEO annual base salary as of October 1, 2026 ($) | D7: Annual (12-month) amount, not monthly or per pay period. Whole dollars. Leave out bonus, housing and vehicle allowances, deferred compensation, and benefits - those are entered later in this section and in 3B. | E7: 218000 | F7: HR / Board | G7: =IF(C7="","To do",IF(NOT(ISNUMBER(C7)),"Check: enter a number only, without symbols",IF(OR(C7<0,C7>99999999999),"Check: must be from 0 to 99,999,999,999",IF(C7<>INT(C7),"Check: whole numbers only",IF(OR(C7<50000,C7>1000000),"Confirm: outside the expected range (50,000 to 1,000,000)",IF(C7<60000,"Confirm: under $60,000 - enter the annual amount","OK"))))))
A8: 3A.2 | B8: Does the President / CEO have an annual bonus or incentive opportunity this year (FY 2026-27)? | D8: Choose Yes or No. | E8: Yes | F8: HR / Board | G8: =IF(C8="","To do","OK")
A9: 3A.3 | B9: This year's maximum bonus opportunity, as a percentage of base salary [Answer only if 3A.2 is Yes.] | D9: Percent with up to one decimal. Enter 3 for 3%, not 0.03. | E9: 10 | F9: HR / Board | G9: =IF(C8="",IF(C9="","Answer 3A.2 first","Check: answer 3A.2 first"),IF(C8="Yes",IF(C9="","To do",IF(NOT(ISNUMBER(C9)),"Check: enter a number only, without symbols",IF(OR(C9<0,C9>999),"Check: must be from 0 to 999",IF(OR(C9<0,C9>100),"Confirm: outside the expected range (0 to 100)",IF(C9>50,"Confirm: over 50% of base","OK"))))),IF(C9="","Not needed","Check: not needed - clear this entry")))
A10: 3A.4 | B10: Did the President / CEO have an annual bonus or incentive opportunity last year (FY 2025-26)? | D10: Choose Yes or No. | E10: Yes | F10: HR / Board | G10: =IF(C10="","To do","OK")
A11: 3A.5 | B11: Bonus paid for last year (FY 2025-26) ($) [Answer only if 3A.4 is Yes.] | D11: Whole dollars. Enter 0 if there was an opportunity but nothing was paid. | E11: 13000 | F11: HR / Board | G11: =IF(C10="",IF(C11="","Answer 3A.4 first","Check: answer 3A.4 first"),IF(C10="Yes",IF(C11="","To do",IF(NOT(ISNUMBER(C11)),"Check: enter a number only, without symbols",IF(OR(C11<0,C11>99999999999),"Check: must be from 0 to 99,999,999,999",IF(C11<>INT(C11),"Check: whole numbers only",IF(OR(C11<0,C11>100000),"Confirm: outside the expected range (0 to 100,000)","OK"))))),IF(C11="","Not needed","Check: not needed - clear this entry")))
A12: 3A.6 | B12: How was last year's bonus amount determined? [Answer only if 3A.4 is Yes.] | D12: Choose from the list. | E12: Discretionary | F12: HR / Board | G12: =IF(C10="",IF(C12="","Answer 3A.4 first","Check: answer 3A.4 first"),IF(C10="Yes",IF(C12="","To do","OK"),IF(C12="","Not needed","Check: not needed - clear this entry")))
A13: 3A.7 | B13: Describe how the bonus was determined [Answer only if 3A.6 is Other.] | D13: Short description. | F13: HR / Board | G13: =IF(C12="",IF(C13="","Answer 3A.6 first","Check: answer 3A.6 first"),IF(C12="Other",IF(C13="","To do","OK"),IF(C13="","Not needed","Check: not needed - clear this entry")))
A14: 3B: Retirement, deferred compensation, and supplemental benefits (employer-funded annual amounts for the current year)
A15: 3B.1 | B15: Employer contribution to the standard retirement plan available to all employees, as a percentage of the President / CEO's base salary | D15: Percent with up to one decimal. Enter 3 for 3%, not 0.03. Enter 0 if none. | E15: 5 | F15: HR | G15: =IF(C15="","To do",IF(NOT(ISNUMBER(C15)),"Check: enter a number only, without symbols",IF(OR(C15<0,C15>999),"Check: must be from 0 to 999",IF(OR(C15<0,C15>20),"Confirm: outside the expected range (0 to 20)","OK"))))
A16: 3B.2 | B16: Annual employer contribution to supplemental or executive plans - 457(b), 457(f), SERP ($) | D16: Whole dollars. Enter 0 if none. | E16: 0 | F16: HR / Board | G16: =IF(C16="","To do",IF(NOT(ISNUMBER(C16)),"Check: enter a number only, without symbols",IF(OR(C16<0,C16>99999999999),"Check: must be from 0 to 99,999,999,999",IF(C16<>INT(C16),"Check: whole numbers only",IF(OR(C16<0,C16>200000),"Confirm: outside the expected range (0 to 200,000)","OK")))))
A17: 3B.3 | B17: Housing or housing allowance ($) | D17: Whole dollars. Enter 0 if not provided. | E17: 30000 | F17: Finance / President's office | G17: =IF(C17="","To do",IF(NOT(ISNUMBER(C17)),"Check: enter a number only, without symbols",IF(OR(C17<0,C17>99999999999),"Check: must be from 0 to 99,999,999,999",IF(C17<>INT(C17),"Check: whole numbers only",IF(OR(C17<0,C17>200000),"Confirm: outside the expected range (0 to 200,000)","OK")))))
A18: 3B.4 | B18: Vehicle or vehicle allowance ($) | D18: Whole dollars. Enter 0 if not provided. | E18: 6000 | F18: Finance / President's office | G18: =IF(C18="","To do",IF(NOT(ISNUMBER(C18)),"Check: enter a number only, without symbols",IF(OR(C18<0,C18>99999999999),"Check: must be from 0 to 99,999,999,999",IF(C18<>INT(C18),"Check: whole numbers only",IF(OR(C18<0,C18>40000),"Confirm: outside the expected range (0 to 40,000)","OK")))))
A19: 3B.5 | B19: Health and social club dues ($) | D19: Whole dollars. Enter 0 if not provided. | E19: 1500 | F19: Finance / President's office | G19: =IF(C19="","To do",IF(NOT(ISNUMBER(C19)),"Check: enter a number only, without symbols",IF(OR(C19<0,C19>99999999999),"Check: must be from 0 to 99,999,999,999",IF(C19<>INT(C19),"Check: whole numbers only",IF(OR(C19<0,C19>30000),"Confirm: outside the expected range (0 to 30,000)","OK")))))
A20: 3B.6 | B20: Executive physical or wellness allowance ($) | D20: Whole dollars. Enter 0 if not provided. | E20: 0 | F20: HR | G20: =IF(C20="","To do",IF(NOT(ISNUMBER(C20)),"Check: enter a number only, without symbols",IF(OR(C20<0,C20>99999999999),"Check: must be from 0 to 99,999,999,999",IF(C20<>INT(C20),"Check: whole numbers only",IF(OR(C20<0,C20>15000),"Confirm: outside the expected range (0 to 15,000)","OK")))))
A21: 3B.7 | B21: Dependent tuition ($) | D21: Whole dollars. Enter 0 if not provided. | E21: 0 | F21: HR | G21: =IF(C21="","To do",IF(NOT(ISNUMBER(C21)),"Check: enter a number only, without symbols",IF(OR(C21<0,C21>99999999999),"Check: must be from 0 to 99,999,999,999",IF(C21<>INT(C21),"Check: whole numbers only",IF(OR(C21<0,C21>100000),"Confirm: outside the expected range (0 to 100,000)","OK")))))
A22: 3B.8 | B22: Phone or technology allowance ($) | D22: Whole dollars. Enter 0 if not provided. | E22: 900 | F22: Finance / President's office | G22: =IF(C22="","To do",IF(NOT(ISNUMBER(C22)),"Check: enter a number only, without symbols",IF(OR(C22<0,C22>99999999999),"Check: must be from 0 to 99,999,999,999",IF(C22<>INT(C22),"Check: whole numbers only",IF(OR(C22<0,C22>6000),"Confirm: outside the expected range (0 to 6,000)","OK")))))
A23: 3B.9 | B23: Executive life insurance - annual premium ($) | D23: Whole dollars. The yearly cost, not the coverage amount. Enter 0 if not provided. | E23: 1800 | F23: HR | G23: =IF(C23="","To do",IF(NOT(ISNUMBER(C23)),"Check: enter a number only, without symbols",IF(OR(C23<0,C23>99999999999),"Check: must be from 0 to 99,999,999,999",IF(C23<>INT(C23),"Check: whole numbers only",IF(OR(C23<0,C23>30000),"Confirm: outside the expected range (0 to 30,000)","OK")))))
A24: 3B.10 | B24: Executive life insurance - coverage (face) amount ($) [Answer only if 3B.9 is more than 0.] | D24: Whole dollars. The amount of coverage, not the yearly cost. | E24: 500000 | F24: HR | G24: =IF(C23="",IF(C24="","Answer 3B.9 first","Check: answer 3B.9 first"),IF(AND(ISNUMBER(C23),C23>0),IF(C24="","To do",IF(NOT(ISNUMBER(C24)),"Check: enter a number only, without symbols",IF(OR(C24<0,C24>99999999999),"Check: must be from 0 to 99,999,999,999",IF(C24<>INT(C24),"Check: whole numbers only",IF(OR(C24<0,C24>3000000),"Confirm: outside the expected range (0 to 3,000,000)","OK"))))),IF(C24="","Not needed","Check: not needed - clear this entry")))
A25: 3B.11 | B25: Executive disability insurance - annual premium ($) | D25: Whole dollars. Enter 0 if not provided. | E25: 0 | F25: HR | G25: =IF(C25="","To do",IF(NOT(ISNUMBER(C25)),"Check: enter a number only, without symbols",IF(OR(C25<0,C25>99999999999),"Check: must be from 0 to 99,999,999,999",IF(C25<>INT(C25),"Check: whole numbers only",IF(OR(C25<0,C25>15000),"Confirm: outside the expected range (0 to 15,000)","OK")))))
A26: 3B.12 | B26: Other supplemental benefits - total annual value ($) | D26: Whole dollars. Enter 0 if none. | E26: 2500 | F26: HR / President's office | G26: =IF(C26="","To do",IF(NOT(ISNUMBER(C26)),"Check: enter a number only, without symbols",IF(OR(C26<0,C26>99999999999),"Check: must be from 0 to 99,999,999,999",IF(C26<>INT(C26),"Check: whole numbers only",IF(OR(C26<0,C26>50000),"Confirm: outside the expected range (0 to 50,000)","OK")))))
A27: 3B.13 | B27: Describe the other supplemental benefits [Answer only if 3B.12 is more than 0.] | D27: Short description. | E27: Long-term care policy | F27: HR / President's office | G27: =IF(C26="",IF(C27="","Answer 3B.12 first","Check: answer 3B.12 first"),IF(AND(ISNUMBER(C26),C26>0),IF(C27="","To do","OK"),IF(C27="","Not needed","Check: not needed - clear this entry")))
A28: 3C: Experience and contract provisions
A29: 3C.1 | B29: Completed years as President / CEO at this institution | D29: Whole number. Enter 0 if this is the first year. | E29: 6 | F29: President's office | G29: =IF(C29="","To do",IF(NOT(ISNUMBER(C29)),"Check: enter a number only, without symbols",IF(OR(C29<0,C29>999999),"Check: must be from 0 to 999,999",IF(C29<>INT(C29),"Check: whole numbers only",IF(OR(C29<0,C29>45),"Confirm: outside the expected range (0 to 45)","OK")))))
A30: 3C.2 | B30: Completed years as a President / CEO at other institutions of higher education before this one | D30: Whole number. Enter 0 if none. | E30: 2 | F30: President's office | G30: =IF(C30="","To do",IF(NOT(ISNUMBER(C30)),"Check: enter a number only, without symbols",IF(OR(C30<0,C30>999999),"Check: must be from 0 to 999,999",IF(C30<>INT(C30),"Check: whole numbers only",IF(OR(C30<0,C30>45),"Confirm: outside the expected range (0 to 45)","OK")))))
A31: 3C.3 | B31: Does the President / CEO have an employment contract for this role? | D31: Choose Yes or No. | E31: Yes | F31: Board / President's office | G31: =IF(C31="","To do","OK")
A32: 3C.4 | B32: What type of contract does the President / CEO have? [Answer only if 3C.3 is Yes.] | D32: Fixed term ends on a set date unless renewed. Evergreen / rolling renews automatically so that a set term always remains. | E32: Fixed term | F32: Board / President's office | G32: =IF(C31="",IF(C32="","Answer 3C.3 first","Check: answer 3C.3 first"),IF(C31="Yes",IF(C32="","To do","OK"),IF(C32="","Not needed","Check: not needed - clear this entry")))
A33: 3C.5 | B33: Describe the contract type [Answer only if 3C.4 is Other.] | D33: Short description. | F33: Board / President's office | G33: =IF(C32="",IF(C33="","Answer 3C.4 first","Check: answer 3C.4 first"),IF(C32="Other",IF(C33="","To do","OK"),IF(C33="","Not needed","Check: not needed - clear this entry")))
A34: 3C.6 | B34: Term of the current contract, in years [Answer only if 3C.4 is Fixed term or Evergreen / rolling.] | D34: Whole number of years. For an evergreen / rolling contract, enter the rolling term. | E34: 3 | F34: Board / President's office | G34: =IF(C32="",IF(C34="","Answer 3C.4 first","Check: answer 3C.4 first"),IF(OR(C32="Fixed term",C32="Evergreen / rolling"),IF(C34="","To do",IF(NOT(ISNUMBER(C34)),"Check: enter a number only, without symbols",IF(OR(C34<0,C34>999999),"Check: must be from 0 to 999,999",IF(C34<>INT(C34),"Check: whole numbers only",IF(OR(C34<1,C34>10),"Confirm: outside the expected range (1 to 10)","OK"))))),IF(C34="","Not needed","Check: not needed - clear this entry")))
A35: 3C.7 | B35: Does the contract have a severance provision for termination without cause? [Answer only if 3C.3 is Yes.] | D35: Choose Yes or No. | E35: Yes | F35: Board / President's office | G35: =IF(C31="",IF(C35="","Answer 3C.3 first","Check: answer 3C.3 first"),IF(C31="Yes",IF(C35="","To do","OK"),IF(C35="","Not needed","Check: not needed - clear this entry")))
A36: 3C.8 | B36: What is the payment basis for severance? [Answer only if 3C.7 is Yes.] | D36: Choose from the list. | E36: Base only | F36: Board / President's office | G36: =IF(C35="",IF(C36="","Answer 3C.7 first","Check: answer 3C.7 first"),IF(C35="Yes",IF(C36="","To do","OK"),IF(C36="","Not needed","Check: not needed - clear this entry")))
A37: 3C.9 | B37: Describe the severance payment basis [Answer only if 3C.8 is Other.] | D37: Short description. | F37: Board / President's office | G37: =IF(C36="",IF(C37="","Answer 3C.8 first","Check: answer 3C.8 first"),IF(C36="Other",IF(C37="","To do","OK"),IF(C37="","Not needed","Check: not needed - clear this entry")))
A38: 3C.10 | B38: Severance term, in months [Answer only if 3C.7 is Yes.] | D38: Whole number of months. | E38: 12 | F38: Board / President's office | G38: =IF(C35="",IF(C38="","Answer 3C.7 first","Check: answer 3C.7 first"),IF(C35="Yes",IF(C38="","To do",IF(NOT(ISNUMBER(C38)),"Check: enter a number only, without symbols",IF(OR(C38<0,C38>999999),"Check: must be from 0 to 999,999",IF(C38<>INT(C38),"Check: whole numbers only",IF(OR(C38<1,C38>36),"Confirm: outside the expected range (1 to 36)","OK"))))),IF(C38="","Not needed","Check: not needed - clear this entry")))
A39: 3C.11 | B39: Does the President / CEO have tenure? | D39: Choose Yes or No. | E39: No | F39: President's office | G39: =IF(C39="","To do","OK")
A40: 3C.12 | B40: Is the President / CEO eligible for sabbatical leave? | D40: Choose Yes or No. | E40: Yes | F40: President's office | G40: =IF(C40="","To do","OK")
A41: 3C.13 | B41: What is the sabbatical leave policy? [Answer only if 3C.12 is Yes.] | D41: Choose from the list. | E41: Different than faculty | F41: President's office | G41: =IF(C40="",IF(C41="","Answer 3C.12 first","Check: answer 3C.12 first"),IF(C40="Yes",IF(C41="","To do","OK"),IF(C41="","Not needed","Check: not needed - clear this entry")))

Sheet 4 Additional
A1: Section 4: Additional Input
A2: Spouse role and any context that helps interpret the figures.
A3: Enter values only in the shaded cells in column C. Column G tells you whether each entry is complete.
A5: Item | B5: Question | C5: Your entry | D5: How to enter | E5: Example | F5: Usually held by | G5: Check
A6: 4.1 | B6: Which category best describes the role of the President / CEO's spouse at the institution? Ceremonial: appears at events and conferences with the President / CEO. Ambassadorial: appears at events and conferences in place of the President / CEO. Institutional: holds a defined position at the institution. Not applicable: no spouse, or no role. | D6: Choose from the list. | E6: Ceremonial | F6: President's office | G6: =IF(C6="","To do","OK")
A7: 4.2 | B7: Annual compensation paid to the spouse by the institution ($) [Answer only if 4.1 is Ceremonial or Ambassadorial or Institutional.] | D7: Whole dollars. Enter 0 if the spouse is not paid. | E7: 0 | F7: HR | G7: =IF(C6="",IF(C7="","Answer 4.1 first","Check: answer 4.1 first"),IF(OR(C6="Ceremonial",C6="Ambassadorial",C6="Institutional"),IF(C7="","To do",IF(NOT(ISNUMBER(C7)),"Check: enter a number only, without symbols",IF(OR(C7<0,C7>99999999999),"Check: must be from 0 to 99,999,999,999",IF(C7<>INT(C7),"Check: whole numbers only",IF(OR(C7<0,C7>400000),"Confirm: outside the expected range (0 to 400,000)","OK"))))),IF(C7="","Not needed","Check: not needed - clear this entry")))
A8: 4.3 | B8: Anything needed to explain or put in context executive compensation practices at your institution | D8: Optional. | F8: Any | G8: =IF(C8="","Optional","OK")
A9: 4.4 | B9: Suggestions for improving next year's survey | D9: Optional. | F9: Any | G9: =IF(C9="","Optional","OK")

Sheet Export
A1: TAG | B1: ITEM | C1: LABEL | D1: VALUE
A2: HIGHEST_DEGREE | B2: 1.1 | C2: Highest degree granted | D2: =IF('1 Institution'!C6="","",'1 Institution'!C6)
A3: FY_END | B3: 1.2 | C3: Last day of your fiscal year | D3: =IF('1 Institution'!C7="","",'1 Institution'!C7)
A4: FY_END_TEXT | B4: 1.3 | C4: Fiscal year end date | D4: =IF('1 Institution'!C8="","",'1 Institution'!C8)
A5: ENDOWMENT | B5: 1.4 | C5: Total endowment - market value at the end of your last fiscal year (FY 2025-26) ($) | D5: =IF('1 Institution'!C9="","",'1 Institution'!C9)
A6: EXPENSES | B6: 1.5 | C6: Total annual expenses for your last fiscal year (FY 2025-26) ($) | D6: =IF('1 Institution'!C10="","",'1 Institution'!C10)
A7: UG_FTE | B7: 1.6 | C7: Undergraduate student full-time equivalent (FTE) for Fall 2026 | D7: =IF('1 Institution'!C11="","",'1 Institution'!C11)
A8: GRAD_FTE | B8: 1.7 | C8: Graduate student full-time equivalent (FTE) for Fall 2026 | D8: =IF('1 Institution'!C12="","",'1 Institution'!C12)
A9: SAL_BUDGET_LAST | B9: 1.8 | C9: Percentage of salary budgeted for increases in the last fiscal year (FY 2025-26) | D9: =IF('1 Institution'!C13="","",'1 Institution'!C13)
A10: SAL_BUDGET_CURRENT | B10: 1.9 | C10: Percentage of salary budgeted for increases in the current fiscal year (FY 2026-27) | D10: =IF('1 Institution'!C14="","",'1 Institution'!C14)
A11: MAX_CONTRIBUTION | B11: 1.10 | C11: Maximum employer contribution, as a percentage of salary, that an employee can earn in the qualified retirement plan | D11: =IF('1 Institution'!C15="","",'1 Institution'!C15)
A12: CFO_YN | B12: 2.1 | C12: Chief Business / Financial Officer - full-time incumbent | D12: =IF('2 Admin Leaders'!C11="","",'2 Admin Leaders'!C11)
A13: CFO_REPORTS | B13: 2.1 | C13: Chief Business / Financial Officer - reports directly to President / CEO | D13: =IF('2 Admin Leaders'!D11="","",'2 Admin Leaders'!D11)
A14: CFO_BASE | B14: 2.1 | C14: Chief Business / Financial Officer - base salary | D14: =IF('2 Admin Leaders'!E11="","",'2 Admin Leaders'!E11)
A15: CFO_BONUS | B15: 2.1 | C15: Chief Business / Financial Officer - bonus paid | D15: =IF('2 Admin Leaders'!F11="","",'2 Admin Leaders'!F11)
A16: CFO_YEARS | B16: 2.1 | C16: Chief Business / Financial Officer - completed years in role | D16: =IF('2 Admin Leaders'!G11="","",'2 Admin Leaders'!G11)
A17: CFO_NOTES | B17: 2.1 | C17: Chief Business / Financial Officer - notes | D17: =IF('2 Admin Leaders'!H11="","",'2 Admin Leaders'!H11)
A18: COO_YN | B18: 2.2 | C18: Chief Operating Officer - full-time incumbent | D18: =IF('2 Admin Leaders'!C12="","",'2 Admin Leaders'!C12)
A19: COO_REPORTS | B19: 2.2 | C19: Chief Operating Officer - reports directly to President / CEO | D19: =IF('2 Admin Leaders'!D12="","",'2 Admin Leaders'!D12)
A20: COO_BASE | B20: 2.2 | C20: Chief Operating Officer - base salary | D20: =IF('2 Admin Leaders'!E12="","",'2 Admin Leaders'!E12)
A21: COO_BONUS | B21: 2.2 | C21: Chief Operating Officer - bonus paid | D21: =IF('2 Admin Leaders'!F12="","",'2 Admin Leaders'!F12)
A22: COO_YEARS | B22: 2.2 | C22: Chief Operating Officer - completed years in role | D22: =IF('2 Admin Leaders'!G12="","",'2 Admin Leaders'!G12)
A23: COO_NOTES | B23: 2.2 | C23: Chief Operating Officer - notes | D23: =IF('2 Admin Leaders'!H12="","",'2 Admin Leaders'!H12)
A24: CONTROLLER_YN | B24: 2.3 | C24: Controller - full-time incumbent | D24: =IF('2 Admin Leaders'!C13="","",'2 Admin Leaders'!C13)
A25: CONTROLLER_REPORTS | B25: 2.3 | C25: Controller - reports directly to President / CEO | D25: =IF('2 Admin Leaders'!D13="","",'2 Admin Leaders'!D13)
A26: CONTROLLER_BASE | B26: 2.3 | C26: Controller - base salary | D26: =IF('2 Admin Leaders'!E13="","",'2 Admin Leaders'!E13)
A27: CONTROLLER_BONUS | B27: 2.3 | C27: Controller - bonus paid | D27: =IF('2 Admin Leaders'!F13="","",'2 Admin Leaders'!F13)
A28: CONTROLLER_YEARS | B28: 2.3 | C28: Controller - completed years in role | D28: =IF('2 Admin Leaders'!G13="","",'2 Admin Leaders'!G13)
A29: CONTROLLER_NOTES | B29: 2.3 | C29: Controller - notes | D29: =IF('2 Admin Leaders'!H13="","",'2 Admin Leaders'!H13)
A30: CHRO_YN | B30: 2.4 | C30: Chief Human Resources Officer - full-time incumbent | D30: =IF('2 Admin Leaders'!C14="","",'2 Admin Leaders'!C14)
A31: CHRO_REPORTS | B31: 2.4 | C31: Chief Human Resources Officer - reports directly to President / CEO | D31: =IF('2 Admin Leaders'!D14="","",'2 Admin Leaders'!D14)
A32: CHRO_BASE | B32: 2.4 | C32: Chief Human Resources Officer - base salary | D32: =IF('2 Admin Leaders'!E14="","",'2 Admin Leaders'!E14)
A33: CHRO_BONUS | B33: 2.4 | C33: Chief Human Resources Officer - bonus paid | D33: =IF('2 Admin Leaders'!F14="","",'2 Admin Leaders'!F14)
A34: CHRO_YEARS | B34: 2.4 | C34: Chief Human Resources Officer - completed years in role | D34: =IF('2 Admin Leaders'!G14="","",'2 Admin Leaders'!G14)
A35: CHRO_NOTES | B35: 2.4 | C35: Chief Human Resources Officer - notes | D35: =IF('2 Admin Leaders'!H14="","",'2 Admin Leaders'!H14)
A36: CIO_YN | B36: 2.5 | C36: Chief Information / Technology Officer - full-time incumbent | D36: =IF('2 Admin Leaders'!C15="","",'2 Admin Leaders'!C15)
A37: CIO_REPORTS | B37: 2.5 | C37: Chief Information / Technology Officer - reports directly to President / CEO | D37: =IF('2 Admin Leaders'!D15="","",'2 Admin Leaders'!D15)
A38: CIO_BASE | B38: 2.5 | C38: Chief Information / Technology Officer - base salary | D38: =IF('2 Admin Leaders'!E15="","",'2 Admin Leaders'!E15)
A39: CIO_BONUS | B39: 2.5 | C39: Chief Information / Technology Officer - bonus paid | D39: =IF('2 Admin Leaders'!F15="","",'2 Admin Leaders'!F15)
A40: CIO_YEARS | B40: 2.5 | C40: Chief Information / Technology Officer - completed years in role | D40: =IF('2 Admin Leaders'!G15="","",'2 Admin Leaders'!G15)
...
